Workbook

Sheet Modelo de Dominio Anémico

Sheet Contexto
A1: Nombre | B1: Descripcion
A2: Razonamiento Cuantitativo | B2: El contexto de Razonamiento Cuantitativo es el encargado de almacenar y organizar la información de cada componente de esta variable, en donde el estudiante realizara actividades para reforzar y estimular sus habilidades en el razonamiento cuantitativo.

Sheet Objeto de Dominio 
A1: Subdominio/Contexto
A2: Nombre | B2: Descripción | C2: Tipo | D2: Contexto
A3: Estudiante | B3: Alumno de primer semestre de la UCO con falencias en Razonamiento Lógico. | C3: Referenciado | D3: Componente Base
A4: Sesión de entrenamiento | B4: Sesión donde el entrenador evalúa las capacidades de razonamiento lógico del estudiante. | C4: Referenciado | D4: Componente Base
A5: Tutorial Tarea | B5: Serie de instrucciones sobre como funciona la tarea antes de la sesión. Representada por un cerebrito de caricatura. | C5: Propio | D5: Razonamiento Cuantitativo
A6: Tutorial Nivel | B6: Serie de instrucciones sobre como funciona un nivel antes de la sesión. Representada por un cerebrito de caricatura. | C6: Propio | D6: Razonamiento Cuantitativo
A7: Tarea | B7: Serie de niveles y estímulos para que el entrenador evalúe las habilidades de razonamiento lógico del estudiante. | C7: Propio | D7: Razonamiento Cuantitativo
A8: Nivel | B8: Subdivisión de una Tarea que aumenta progresivamente su dificultad. | C8: Propio | D8: Razonamiento Cuantitativo
A9: Estímulo | B9: Elementos únicos de cada nível para que el estudiante interactúe con las tareas. | C9: Propio | D9: Razonamiento Cuantitativo
A10: Respuesta Estimulo | B10: Respuestas del estudiante por cada estímulo durante una sesión. | C10: Propio | D10: Razonamiento Cuantitativo
A11: Opción de Respuesta | B11: Cada opcion de respuesta única de un estimulo. | C11: Propio | D11: Razonamiento Cuantitativo

Sheet Tutorial Tarea
A1: Identificador | B1: Tarea | C1: Indice de Mensaje | D1: Tiempo Límite (En Segundos) | E1: Mensaje | F1: CU
A2: 1 | B2: =Tarea!B2 -> El Suelo es Lava | C2: 1 | D2: 20 | E2: Estamos dentro de un volcán y para sobrevivir en él deberás analizar las imágenes que aparecerán en las rocas y hallar cuál de estas no tiene relación con las demás, solo una no se relacionará. Tu objetivo consistirá en descubrir cuál de estas es y saltar hasta la roca donde esta se encuentra antes que el tiempo se agote y caigas a la lava. (Recuerda la relación puede ser por forma, color o cantidad.) | F2: ="Mensaje Tarea - "&B2&" - "&C2 -> Mensaje Tarea - El Suelo es Lava - 1
A3: 2 | B3: =Tarea!B2 -> El Suelo es Lava | C3: 2 | D3: 45 | E3: Para moverte deberás usar las letras del teclado; con la letra A te moverás a la izquierda, con la letra D a la derecha y con la letra W saltarás. W + A = salto a la izquierda W + D = salto a la derecha Ahora inténtalo tú. | F3: ="Mensaje Tarea - "&B3&" - "&C3 -> Mensaje Tarea - El Suelo es Lava - 2
A4: 3 | B4: =Tarea!B2 -> El Suelo es Lava | C4: 3 | D4: 25 | E4: El logo que aparece en la parte superior derecha de tu pantalla Equivale a puntos que obtendrás a medida que vayas jugando y podrás intercambiar por recompensas más adelante. | F4: ="Mensaje Tarea - "&B4&" - "&C4 -> Mensaje Tarea - El Suelo es Lava - 3
A5: 4 | B5: =Tarea!B2 -> El Suelo es Lava | C5: 4 | D5: 15 | E5: El logo que aparece en la parte superior izquierda de tu pantalla Equivale al número de vidas que posees. Cada vez que toques la lava perderás una vida. | F5: ="Mensaje Tarea - "&B5&" - "&C5 -> Mensaje Tarea - El Suelo es Lava - 4
A6: 5 | B6: =Tarea!B2 -> El Suelo es Lava | C6: 5 | D6: 15 | E6: El logo que aparece en la parte superior central de tu pantalla Equivale al tiempo que te queda para elegir una opción. A medida que el tiempo disminuye el círculo ira prendiendo circunferencia. | F6: ="Mensaje Tarea - "&B6&" - "&C6 -> Mensaje Tarea - El Suelo es Lava - 5
A7: 6 | B7: =Tarea!B2 -> El Suelo es Lava | C7: 6 | D7: 15 | E7: Por último, en la parte inferior izquierda de tu pantalla se llevará la cuenta de tus aciertos. | F7: ="Mensaje Tarea - "&B7&" - "&C7 -> Mensaje Tarea - El Suelo es Lava - 6
A8: 7 | B8: =Tarea!B3 -> Los Secretos del Chef | C8: 1 | D8: 10 | E8: Hola de nuevo, me alegra verte, hoy conocerás una nueva versión de nuestro laboratorio, en la cual nos encargamos de agregarles nutrientes a los alimentos para que la comida de nuestra cafetería tenga un mejor sabor y aporte más energía a cada uno de nuestros clientes. | F8: ="Mensaje Tarea - "&B8&" - "&C8 -> Mensaje Tarea - Los Secretos del Chef - 1
A9: 8 | B9: =Tarea!B3 -> Los Secretos del Chef | C9: 2 | D9: 10 | E9: El día de hoy vamos a realizar diversas mezclas de químicos basados en los colores para generar un grupo de compuestos y nutrientes necesarios para la fabricación de alimentos que se venderán en la cafetería. Contamos con tu ayuda. | F9: ="Mensaje Tarea - "&B9&" - "&C9 -> Mensaje Tarea - Los Secretos del Chef - 2
A10: 9 | B10: =Tarea!B3 -> Los Secretos del Chef | C10: 3 | D10: 10 | E10: En este nivel tendremos que mezclar diversos químicos identificados por colores con el objetivo de que quede igual al ejemplo que se mostrara en la parte superior de la pantalla, esto para obtener el mejor café posible. | F10: ="Mensaje Tarea - "&B10&" - "&C10 -> Mensaje Tarea - Los Secretos del Chef - 3
A11: 10 | B11: =Tarea!B3 -> Los Secretos del Chef | C11: 4 | D11: 5 | E11: Los químicos con los que trabajaremos en esta tarea son: 🟡 🔵 🔴 | F11: ="Mensaje Tarea - "&B11&" - "&C11 -> Mensaje Tarea - Los Secretos del Chef - 4
A12: 11 | B12: =Tarea!B3 -> Los Secretos del Chef | C12: 5 | D12: 10 | E12: Dentro de cada estímulo tendrás el ejemplo en la parte superior y en la parte inferior el espacio donde tú lo debes realizar. Así: | F12: ="Mensaje Tarea - "&B12&" - "&C12 -> Mensaje Tarea - Los Secretos del Chef - 5
A13: 12 | B13: =Tarea!B3 -> Los Secretos del Chef | C13: 6 | D13: 5 | E13: Ejemplo en la parte superior, espacio para realizarlo en la parte inferior. | F13: ="Mensaje Tarea - "&B13&" - "&C13 -> Mensaje Tarea - Los Secretos del Chef - 6
A14: 13 | B14: =Tarea!B3 -> Los Secretos del Chef | C14: 7 | D14: 10 | E14: En este nivel podrás mover los químicos para que formen la misma secuencia que el ejemplo. Para esto deberás usar el mouse del computador y arrastrar el químico por los espacios que se requiera. Estos, a medida que el color pase por ellos, se pintarán del mismo. A su vez, puedes mover varios colores por un mismo espacio y los colores se mezclarán cuando se junten en una misma casilla. | F14: ="Mensaje Tarea - "&B14&" - "&C14 -> Mensaje Tarea - Los Secretos del Chef - 7
A15: 14 | B15: =Tarea!B3 -> Los Secretos del Chef | C15: 8 | D15: 15 | E15: Para realizar esta actividad cuentas con un tiempo determinado por cada estímulo el cual será de 42 segundos, e iniciarás con 3 vidas las cuales perderás si se acaba el tiempo y no has hecho la mezcla. | F15: ="Mensaje Tarea - "&B15&" - "&C15 -> Mensaje Tarea - Los Secretos del Chef - 8
A16: 15 | B16: =Tarea!B4 -> Clonacion | C16: 1 | D16: 30 | E16: Hola, me alegra verte, justo te necesitábamos, el día de hoy vamos a clonar a nuestras ratas de laboratorio, ninguna de ellas va a sufrir daño, pero para eso necesitamos tu ayuda, para lograr hacer el experimento de forma correcta deberás utilizar la lógica en las distintas pruebas que tendremos, para estas necesitarás utilizar el mouse de tu computador para manipular los objetos que en estas aparezcan así como el teclado. ¿Estás listo? | F16: ="Mensaje Tarea - "&B16&" - "&C16 -> Mensaje Tarea - Clonacion - 1
A17: 16 | B17: =Tarea!B4 -> Clonacion | C17: 2 | D17: 30 | E17: Es hora de que conozcas algunos de los instrumentos que usaremos el día de hoy: Molécula | Cadena de ADN | Ratas | Embudo | F17: ="Mensaje Tarea - "&B17&" - "&C17 -> Mensaje Tarea - Clonacion - 2
A18: 17 | B18: =Tarea!B4 -> Clonacion | C18: 3 | D18: 15 | E18: Ahora que conoces todos los instrumentos, estás listo para iniciar. Recuerda que en algunas situaciones deberás usar el mouse de tu computadora y en otras el teclado, pero en todas deberás usar tu razonamiento. Buena suerte. | F18: ="Mensaje Tarea - "&B18&" - "&C18 -> Mensaje Tarea - Clonacion - 3
A19: 18 | B19: =Tarea!B5 -> Todo en Orden | C19: 1 | D19: 10 | E19: El día de hoy queremos organizar varios instrumentos del laboratorio ya que se han ido desacomodando luego de los experimentos. Contamos con tu ayuda. | F19: ="Mensaje Tarea - "&B19&" - "&C19 -> Mensaje Tarea - Todo en Orden - 1
A20: 19 | B20: =Tarea!B5 -> Todo en Orden | C20: 2 | D20: 30 | E20: En esta primera actividad vamos a organizar los instrumentos del laboratorio de la mejor manera posible optimizando el espacio con el que contamos. Para iniciar este nivel haz click en la estantería. | F20: ="Mensaje Tarea - "&B20&" - "&C20 -> Mensaje Tarea - Todo en Orden - 2
A21: 20 | B21: =Tarea!B5 -> Todo en Orden | C21: 3 | D21: 15 | E21: Estamos en la primera actividad, en esta necesitaremos acomodar algunos instrumentos de la mejor manera posible para optimizar el espacio con el que contamos en la estantería. El objetivo es hacer caer piezas e ir rellenando huecos para conseguir hacer líneas. Una vez creadas, desaparecerán y sumarás 1 punto. Si consigues hacer una de cuatro sumarás 10 puntos. | F21: ="Mensaje Tarea - "&B21&" - "&C21 -> Mensaje Tarea - Todo en Orden - 3
A22: 21 | B22: =Tarea!B5 -> Todo en Orden | C22: 4 | D22: 15 | E22: Para realizar esta tarea debemos utilizar las flechas del teclado para mover las figuras y la barra espaciadora para rotarlas de posición. | F22: ="Mensaje Tarea - "&B22&" - "&C22 -> Mensaje Tarea - Todo en Orden - 4
A23: 22 | B23: =Tarea!B5 -> Todo en Orden | C23: 5 | D23: 20 | E23: Estos serán los instrumentos que deberemos acomodar con su respectiva medida. | F23: ="Mensaje Tarea - "&B23&" - "&C23 -> Mensaje Tarea - Todo en Orden - 5
A24: 23 | B24: =Tarea!B5 -> Todo en Orden | C24: 6 | D24: 20 | E24: Por último debes saber que en la parte superior izquierda aparecerá un cuadro donde te mostrarán el siguiente instrumento en salir, y estos saldrán cada 7 segundos. | F24: ="Mensaje Tarea - "&B24&" - "&C24 -> Mensaje Tarea - Todo en Orden - 6

Sheet Tarea
A1: Identificador | B1: Nombre | C1: CU
A2: 1 | B2: El Suelo es Lava | C2: ="Tarea "&A2&" - "&B2 -> Tarea 1 - El Suelo es Lava
A3: 2 | B3: Los Secretos del Chef | C3: ="Tarea "&A3&" - "&B3 -> Tarea 2 - Los Secretos del Chef
A4: 3 | B4: Clonacion | C4: ="Tarea "&A4&" - "&B4 -> Tarea 3 - Clonacion
A5: 4 | B5: Todo en Orden | C5: ="Tarea "&A5&" - "&B5 -> Tarea 4 - Todo en Orden

Sheet Tutorial Nivel
A1: Identificador | B1: Nivel | C1: Indice de Mensaje | D1: Tiempo Límite (En Segundos) | E1: Mensaje | F1: CU
A2: 1 | B2: =Nivel!D2 -> El Suelo es Lava - Nivel 1 | C2: 1 | D2: 15 | E2: Ahora que sabes todo lo que necesitas para sobrevivir estás listo para iniciar. Haz click en iniciar cuando estés listo. | F2: ="Mensaje Nivel - "&B2&" - "&C2 -> Mensaje Nivel - El Suelo es Lava - Nivel 1 - 1
A3: 2 | B3: =Nivel!D3 -> El Suelo es Lava - Nivel 2 | C3: 1 | D3: 10 | E3: ¿Listo para iniciar? Estos serán los estímulos de este nivel; Cuadernos (Blanco y negro), Lápices (Blanco y negro), Borradores (Blanco y negro) | F3: ="Mensaje Nivel - "&B3&" - "&C3 -> Mensaje Nivel - El Suelo es Lava - Nivel 2 - 1
A4: 3 | B4: =Nivel!D5 -> Los Secretos del Chef - Nivel 1 | C4: 1 | D4: 5 | E4: Ya estás listo para iniciar, buena suerte, esperamos lo mejor de ti. | F4: ="Mensaje Nivel - "&B4&" - "&C4 -> Mensaje Nivel - Los Secretos del Chef - Nivel 1 - 1
A5: 4 | B5: =Nivel!D8 -> Clonacion - Nivel 1 | C5: 1 | D5: 15 | E5: Para desarrollar las siguientes actividades contarás con un tiempo determinado el cual no se mostrará en pantalla, cuando solo te queden 30 segundos la pantalla comenzará a vibrar, ahí tendrás que darte prisa. Recuerda cuentas con 3 vidas, cada una de estas se pierde si realizas mal un ejercicio. | F5: ="Mensaje Nivel - "&B5&" - "&C5 -> Mensaje Nivel - Clonacion - Nivel 1 - 1
A6: 5 | B6: =Nivel!D11 -> Todo en Orden - Nivel 1 | C6: 1 | D6: 20 | E6: Ahora que sabes esto ya estás listo para iniciar. Buena suerte. | F6: ="Mensaje Nivel - "&B6&" - "&C6 -> Mensaje Nivel - Todo en Orden - Nivel 1 - 1

Sheet Nivel
A1: Identificador | B1: Intensidad | C1: Tarea | D1: CU
A2: 1 | B2: 1 | C2: =Tarea!B2 -> El Suelo es Lava | D2: =C2&" - Nivel "&B2 -> El Suelo es Lava - Nivel 1
A3: 2 | B3: 2 | C3: =Tarea!B2 -> El Suelo es Lava | D3: =C3&" - Nivel "&B3 -> El Suelo es Lava - Nivel 2
A4: 3 | B4: 3 | C4: =Tarea!B2 -> El Suelo es Lava | D4: =C4&" - Nivel "&B4 -> El Suelo es Lava - Nivel 3
A5: 4 | B5: 1 | C5: =Tarea!B3 -> Los Secretos del Chef | D5: =C5&" - Nivel "&B5 -> Los Secretos del Chef - Nivel 1
A6: 5 | B6: 2 | C6: =Tarea!B3 -> Los Secretos del Chef | D6: =C6&" - Nivel "&B6 -> Los Secretos del Chef - Nivel 2
A7: 6 | B7: 3 | C7: =Tarea!B3 -> Los Secretos del Chef | D7: =C7&" - Nivel "&B7 -> Los Secretos del Chef - Nivel 3
A8: 7 | B8: 1 | C8: =Tarea!B4 -> Clonacion | D8: =C8&" - Nivel "&B8 -> Clonacion - Nivel 1
A9: 8 | B9: 2 | C9: =Tarea!B4 -> Clonacion | D9: =C9&" - Nivel "&B9 -> Clonacion - Nivel 2
A10: 9 | B10: 3 | C10: =Tarea!B4 -> Clonacion | D10: =C10&" - Nivel "&B10 -> Clonacion - Nivel 3
A11: 10 | B11: 1 | C11: =Tarea!B5 -> Todo en Orden | D11: =C11&" - Nivel "&B11 -> Todo en Orden - Nivel 1
A12: 11 | B12: 2 | C12: =Tarea!B5 -> Todo en Orden | D12: =C12&" - Nivel "&B12 -> Todo en Orden - Nivel 2
A13: 12 | B13: 3 | C13: =Tarea!B5 -> Todo en Orden | D13: =C13&" - Nivel "&B13 -> Todo en Orden - Nivel 3

Sheet Estimulo
A1: Identificador | B1: Nivel | C1: Estímulo | D1: Pregunta | E1: Respuesta Correcta | F1: Tiempo Límite en Segundos | G1: CU
A2: 1 | B2: =Nivel!D2 -> El Suelo es Lava - Nivel 1 | C2: 1 | D2: "Identifique el patron que no pertenece." | E2: ='Opción Respuesta'!F3 -> Estimulo El Suelo es Lava - Nivel 1 - 1 - Opcion 2 | F2: 30 | G2: ="Estimulo "&B2&" - "&C2 -> Estimulo El Suelo es Lava - Nivel 1 - 1
A3: 2 | B3: =Nivel!D2 -> El Suelo es Lava - Nivel 1 | C3: 2 | D3: "Identifique el patron que no pertenece." | E3: ='Opción Respuesta'!F5 -> Estimulo El Suelo es Lava - Nivel 1 - 2 - Opcion 1 | F3: 30 | G3: ="Estimulo "&B3&" - "&C3 -> Estimulo El Suelo es Lava - Nivel 1 - 2
A4: 3 | B4: =Nivel!D2 -> El Suelo es Lava - Nivel 1 | C4: 3 | D4: "Identifique el patron que no pertenece." | E4: ='Opción Respuesta'!F10 -> Estimulo El Suelo es Lava - Nivel 1 - 3 - Opcion 3 | F4: 30 | G4: ="Estimulo "&B4&" - "&C4 -> Estimulo El Suelo es Lava - Nivel 1 - 3
A5: 4 | B5: =Nivel!D2 -> El Suelo es Lava - Nivel 1 | C5: 4 | D5: "Identifique el patron que no pertenece." | E5: ='Opción Respuesta'!F11 -> Estimulo El Suelo es Lava - Nivel 1 - 4 - Opcion 1 | F5: 30 | G5: ="Estimulo "&B5&" - "&C5 -> Estimulo El Suelo es Lava - Nivel 1 - 4
A6: 5 | B6: =Nivel!D2 -> El Suelo es Lava - Nivel 1 | C6: 5 | D6: "Identifique el patron que no pertenece." | E6: ='Opción Respuesta'!F16 -> Estimulo El Suelo es Lava - Nivel 1 - 5 - Opcion 3 | F6: 30 | G6: ="Estimulo "&B6&" - "&C6 -> Estimulo El Suelo es Lava - Nivel 1 - 5
A7: 6 | B7: =Nivel!D2 -> El Suelo es Lava - Nivel 1 | C7: 6 | D7: "Identifique el patron que no pertenece." | E7: ='Opción Respuesta'!F18 -> Estimulo El Suelo es Lava - Nivel 1 - 6 - Opcion 2 | F7: 30 | G7: ="Estimulo "&B7&" - "&C7 -> Estimulo El Suelo es Lava - Nivel 1 - 6
A8: 7 | B8: =Nivel!D2 -> El Suelo es Lava - Nivel 1 | C8: 7 | D8: "Identifique el patron que no pertenece." | E8: ='Opción Respuesta'!F22 -> Estimulo El Suelo es Lava - Nivel 1 - 7 - Opcion 3 | F8: 30 | G8: ="Estimulo "&B8&" - "&C8 -> Estimulo El Suelo es Lava - Nivel 1 - 7
A9: 8 | B9: =Nivel!D3 -> El Suelo es Lava - Nivel 2 | C9: 1 | D9: "Identifique el patron que no pertenece." | E9: ='Opción Respuesta'!F25 -> Estimulo El Suelo es Lava - Nivel 2 - 1 - Opcion 3 | F9: 30 | G9: ="Estimulo "&B9&" - "&C9 -> Estimulo El Suelo es Lava - Nivel 2 - 1
A10: 9 | B10: =Nivel!D3 -> El Suelo es Lava - Nivel 2 | C10: 2 | D10: "Identifique el patron que no pertenece." | E10: ='Opción Respuesta'!F27 -> Estimulo El Suelo es Lava - Nivel 2 - 2 - Opcion 2 | F10: 30 | G10: ="Estimulo "&B10&" - "&C10 -> Estimulo El Suelo es Lava - Nivel 2 - 2
A11: 10 | B11: =Nivel!D3 -> El Suelo es Lava - Nivel 2 | C11: 3 | D11: "Identifique el patron que no pertenece." | E11: ='Opción Respuesta'!F31 -> Estimulo El Suelo es Lava - Nivel 2 - 3 - Opcion 3 | F11: 30 | G11: ="Estimulo "&B11&" - "&C11 -> Estimulo El Suelo es Lava - Nivel 2 - 3
A12: 11 | B12: =Nivel!D4 -> El Suelo es Lava - Nivel 3 | C12: 1 | D12: "Identifique el patron que no pertenece." | E12: ='Opción Respuesta'!F35 -> Estimulo El Suelo es Lava - Nivel 3 - 1 - Opcion 4 | F12: 45 | G12: ="Estimulo "&B12&" - "&C12 -> Estimulo El Suelo es Lava - Nivel 3 - 1
A13: 12 | B13: =Nivel!D4 -> El Suelo es Lava - Nivel 3 | C13: 2 | D13: "Identifique el patron que no pertenece." | E13: ='Opción Respuesta'!F38 -> Estimulo El Suelo es Lava - Nivel 3 - 2 - Opcion 3 | F13: 45 | G13: ="Estimulo "&B13&" - "&C13 -> Estimulo El Suelo es Lava - Nivel 3 - 2
A14: 13 | B14: =Nivel!D5 -> Los Secretos del Chef - Nivel 1 | C14: 1 | D14: "Replique la tabla en la parte superior." | E14: ='Opción Respuesta'!F40 -> Estimulo Los Secretos del Chef - Nivel 1 - 1 - Opcion 1 | F14: 42 | G14: ="Estimulo "&B14&" - "&C14 -> Estimulo Los Secretos del Chef - Nivel 1 - 1
A15: 14 | B15: =Nivel!D6 -> Los Secretos del Chef - Nivel 2 | C15: 1 | D15: "Organice los tubos." | E15: ='Opción Respuesta'!F44 -> Estimulo Los Secretos del Chef - Nivel 2 - 1 - Opcion 4 | F15: 45 | G15: ="Estimulo "&B15&" - "&C15 -> Estimulo Los Secretos del Chef - Nivel 2 - 1
A16: 15 | B16: =Nivel!D7 -> Los Secretos del Chef - Nivel 3 | C16: 1 | D16: "Replique la tabla en la parte superior." | E16: ='Opción Respuesta'!F45 -> Estimulo Los Secretos del Chef - Nivel 3 - 1 - Opcion 1 | F16: 42 | G16: ="Estimulo "&B16&" - "&C16 -> Estimulo Los Secretos del Chef - Nivel 3 - 1
A17: 16 | B17: =Nivel!D8 -> Clonacion - Nivel 1 | C17: 1 | D17: "En nuestro laboratorio la reproducción de ratas es de 4 crías por pareja cada seis meses, desde que nacen se pueden reproducir, ¿en cuánto tiempo tendremos 9 parejas de ratas si solo contamos con una pareja inicia?" | E17: ='Opción Respuesta'!F46 -> Estimulo Clonacion - Nivel 1 - 1 - Opcion 1 | F17: 300 | G17: ="Estimulo "&B17&" - "&C17 -> Estimulo Clonacion - Nivel 1 - 1
A18: 17 | B18: =Nivel!D8 -> Clonacion - Nivel 1 | C18: 2 | D18: "En el laboratorio utilizamos un lenguaje artificial para referirnos a ciertas palabras claves, estas palabras se traducen en números. Así: Tubo = 12234, Pipeta = 5657128, Vidrio = 1160964, Embalar = 71381389. Pero se nos acaba de perder el número de la palabra Embudo, podrías ayudarnos y decirnos ¿Cuál sería el código de la palabra Embudo?" | E18: ='Opción Respuesta'!F49 -> Estimulo Clonacion - Nivel 1 - 2 - Opcion 3 | F18: 300 | G18: ="Estimulo "&B18&" - "&C18 -> Estimulo Clonacion - Nivel 1 - 2
A19: 18 | B19: =Nivel!D8 -> Clonacion - Nivel 1 | C19: 3 | D19: "Ahora estamos organizando una cadena de ADN pero necesitamos que cada enlace esté ubicado en fila india, de tal manera que tres enlaces queden detrás de tres enlaces. ¿Cuántos enlaces necesitaríamos como mínimo?" | E19: ='Opción Respuesta'!F51 -> Estimulo Clonacion - Nivel 1 - 3 - Opcion 1 | F19: 240 | G19: ="Estimulo "&B19&" - "&C19 -> Estimulo Clonacion - Nivel 1 - 3
A20: 19 | B20: =Nivel!D11 -> Todo en Orden - Nivel 1 | C20: 1 | D20: "Evite poner una ficha en el limite superior." | E20: ='Opción Respuesta'!F55 -> Estimulo Todo en Orden - Nivel 1 - 1 - Opcion 1 | F20: 420 | G20: ="Estimulo "&B20&" - "&C20 -> Estimulo Todo en Orden - Nivel 1 - 1
A21: 20 | B21: =Nivel!D12 -> Todo en Orden - Nivel 2 | C21: 1 | D21: "Seleccione dos numeros que, al operarlos (suma, resta, multiplicacion, division), resultan en el numero del centro. | E21: ='Opción Respuesta'!F56 -> Estimulo Todo en Orden - Nivel 2 - 1 - Opcion 1 | F21: 600 | G21: ="Estimulo "&B21&" - "&C21 -> Estimulo Todo en Orden - Nivel 2 - 1
A22: 21 | B22: =Nivel!D13 -> Todo en Orden - Nivel 3 | C22: 1 | D22: "Encuentre el orden adecuado de los colores." | E22: ='Opción Respuesta'!F57 -> Estimulo Todo en Orden - Nivel 3 - 1 - Opcion 1 | F22: 60 | G22: ="Estimulo "&B22&" - "&C22 -> Estimulo Todo en Orden - Nivel 3 - 1
A23: 22 | B23: =Nivel!D13 -> Todo en Orden - Nivel 3 | C23: 2 | D23: "Encuentre el orden adecuado de los colores." | E23: ='Opción Respuesta'!F58 -> Estimulo Todo en Orden - Nivel 3 - 2 - Opcion 2 | F23: 60 | G23: ="Estimulo "&B23&" - "&C23 -> Estimulo Todo en Orden - Nivel 3 - 2
A24: 23 | B24: =Nivel!D13 -> Todo en Orden - Nivel 3 | C24: 3 | D24: "Encuentre el orden adecuado de los colores." | E24: ='Opción Respuesta'!F59 -> Estimulo Todo en Orden - Nivel 3 - 3 - Opcion 3 | F24: 60 | G24: ="Estimulo "&B24&" - "&C24 -> Estimulo Todo en Orden - Nivel 3 - 3
A25: 24 | B25: =Nivel!D13 -> Todo en Orden - Nivel 3 | C25: 4 | D25: "Encuentre el orden adecuado de los colores." | E25: ='Opción Respuesta'!F60 -> Estimulo Todo en Orden - Nivel 3 - 4 - Opcion 4 | F25: 120 | G25: ="Estimulo "&B25&" - "&C25 -> Estimulo Todo en Orden - Nivel 3 - 4
A26: 25 | B26: =Nivel!D13 -> Todo en Orden - Nivel 3 | C26: 5 | D26: "Encuentre el orden adecuado de los colores." | E26: ='Opción Respuesta'!F61 -> Estimulo Todo en Orden - Nivel 3 - 5 - Opcion 5 | F26: 120 | G26: ="Estimulo "&B26&" - "&C26 -> Estimulo Todo en Orden - Nivel 3 - 5
A27: 26 | B27: =Nivel!D13 -> Todo en Orden - Nivel 3 | C27: 6 | D27: "Encuentre el orden adecuado de los colores." | E27: ='Opción Respuesta'!F62 -> Estimulo Todo en Orden - Nivel 3 - 6 - Opcion 6 | F27: 120 | G27: ="Estimulo "&B27&" - "&C27 -> Estimulo Todo en Orden - Nivel 3 - 6
A28: 27 | B28: =Nivel!D13 -> Todo en Orden - Nivel 3 | C28: 7 | D28: "Encuentre el orden adecuado de los colores." | E28: ='Opción Respuesta'!F63 -> Estimulo Todo en Orden - Nivel 3 - 7 - Opcion 7 | F28: 120 | G28: ="Estimulo "&B28&" - "&C28 -> Estimulo Todo en Orden - Nivel 3 - 7
A29: 28 | B29: =Nivel!D13 -> Todo en Orden - Nivel 3 | C29: 8 | D29: "Encuentre el orden adecuado de los colores." | E29: ='Opción Respuesta'!F64 -> Estimulo Todo en Orden - Nivel 3 - 8 - Opcion 8 | F29: 180 | G29: ="Estimulo "&B29&" - "&C29 -> Estimulo Todo en Orden - Nivel 3 - 8
A30: 29 | B30: =Nivel!D13 -> Todo en Orden - Nivel 3 | C30: 9 | D30: "Encuentre el orden adecuado de los colores." | E30: ='Opción Respuesta'!F65 -> Estimulo Todo en Orden - Nivel 3 - 9 - Opcion 9 | F30: 180 | G30: ="Estimulo "&B30&" - "&C30 -> Estimulo Todo en Orden - Nivel 3 - 9
A31: 30 | B31: =Nivel!D13 -> Todo en Orden - Nivel 3 | C31: 10 | D31: "Encuentre el orden adecuado de los colores." | E31: ='Opción Respuesta'!F66 -> Estimulo Todo en Orden - Nivel 3 - 10 - Opcion 10 | F31: 180 | G31: ="Estimulo "&B31&" - "&C31 -> Estimulo Todo en Orden - Nivel 3 - 10
A32: 31 | B32: =Nivel!D13 -> Todo en Orden - Nivel 3 | C32: 11 | D32: "Encuentre el orden adecuado de los colores." | E32: ='Opción Respuesta'!F67 -> Estimulo Todo en Orden - Nivel 3 - 11 - Opcion 11 | F32: 180 | G32: ="Estimulo "&B32&" - "&C32 -> Estimulo Todo en Orden - Nivel 3 - 11

Sheet Opción Respuesta
A1: Identificador | B1: Estimulo | C1: Opcion | D1: Detalle | E1: Respuesta Correcta | F1: CU
A2: 1 | B2: =Estimulo!G2 -> Estimulo El Suelo es Lava - Nivel 1 - 1 | C2: 1 | D2: "3 Cuadernos" | E2: NO | F2: =B2&" - Opcion "&C2 -> Estimulo El Suelo es Lava - Nivel 1 - 1 - Opcion 1
A3: 2 | B3: =Estimulo!G2 -> Estimulo El Suelo es Lava - Nivel 1 - 1 | C3: 2 | D3: "4 Lapices" | E3: SI | F3: =B3&" - Opcion "&C3 -> Estimulo El Suelo es Lava - Nivel 1 - 1 - Opcion 2
A4: 3 | B4: =Estimulo!G2 -> Estimulo El Suelo es Lava - Nivel 1 - 1 | C4: 3 | D4: "2 Cuadernos" | E4: NO | F4: =B4&" - Opcion "&C4 -> Estimulo El Suelo es Lava - Nivel 1 - 1 - Opcion 3
A5: 4 | B5: =Estimulo!G3 -> Estimulo El Suelo es Lava - Nivel 1 - 2 | C5: 1 | D5: "3 Cuadernos" | E5: SI | F5: =B5&" - Opcion "&C5 -> Estimulo El Suelo es Lava - Nivel 1 - 2 - Opcion 1
A6: 5 | B6: =Estimulo!G3 -> Estimulo El Suelo es Lava - Nivel 1 - 2 | C6: 2 | D6: "4 Cuadernos" | E6: NO | F6: =B6&" - Opcion "&C6 -> Estimulo El Suelo es Lava - Nivel 1 - 2 - Opcion 2
A7: 6 | B7: =Estimulo!G3 -> Estimulo El Suelo es Lava - Nivel 1 - 2 | C7: 3 | D7: "4 Cuadernos" | E7: NO | F7: =B7&" - Opcion "&C7 -> Estimulo El Suelo es Lava - Nivel 1 - 2 - Opcion 3
A8: 7 | B8: =Estimulo!G4 -> Estimulo El Suelo es Lava - Nivel 1 - 3 | C8: 1 | D8: "4 Lapices" | E8: NO | F8: =B8&" - Opcion "&C8 -> Estimulo El Suelo es Lava - Nivel 1 - 3 - Opcion 1
A9: 8 | B9: =Estimulo!G4 -> Estimulo El Suelo es Lava - Nivel 1 - 3 | C9: 2 | D9: "4 Lapices" | E9: NO | F9: =B9&" - Opcion "&C9 -> Estimulo El Suelo es Lava - Nivel 1 - 3 - Opcion 2
A10: 9 | B10: =Estimulo!G4 -> Estimulo El Suelo es Lava - Nivel 1 - 3 | C10: 3 | D10: "5 Lapices" | E10: SI | F10: =B10&" - Opcion "&C10 -> Estimulo El Suelo es Lava - Nivel 1 - 3 - Opcion 3
A11: 10 | B11: =Estimulo!G5 -> Estimulo El Suelo es Lava - Nivel 1 - 4 | C11: 1 | D11: "5 Cuadernos" | E11: SI | F11: =B11&" - Opcion "&C11 -> Estimulo El Suelo es Lava - Nivel 1 - 4 - Opcion 1
A12: 11 | B12: =Estimulo!G5 -> Estimulo El Suelo es Lava - Nivel 1 - 4 | C12: 2 | D12: "4 Cuadernos" | E12: NO | F12: =B12&" - Opcion "&C12 -> Estimulo El Suelo es Lava - Nivel 1 - 4 - Opcion 2
A13: 12 | B13: =Estimulo!G5 -> Estimulo El Suelo es Lava - Nivel 1 - 4 | C13: 3 | D13: "4 Cuadernos" | E13: NO | F13: =B13&" - Opcion "&C13 -> Estimulo El Suelo es Lava - Nivel 1 - 4 - Opcion 3
A14: 13 | B14: =Estimulo!G6 -> Estimulo El Suelo es Lava - Nivel 1 - 5 | C14: 1 | D14: "6 Cuadernos" | E14: NO | F14: =B14&" - Opcion "&C14 -> Estimulo El Suelo es Lava - Nivel 1 - 5 - Opcion 1
A15: 14 | B15: =Estimulo!G6 -> Estimulo El Suelo es Lava - Nivel 1 - 5 | C15: 2 | D15: "6 Cuadernos" | E15: NO | F15: =B15&" - Opcion "&C15 -> Estimulo El Suelo es Lava - Nivel 1 - 5 - Opcion 2
A16: 15 | B16: =Estimulo!G6 -> Estimulo El Suelo es Lava - Nivel 1 - 5 | C16: 3 | D16: "5 Cuadernos" | E16: SI | F16: =B16&" - Opcion "&C16 -> Estimulo El Suelo es Lava - Nivel 1 - 5 - Opcion 3
A17: 16 | B17: =Estimulo!G7 -> Estimulo El Suelo es Lava - Nivel 1 - 6 | C17: 1 | D17: "6 Lapices" | E17: NO | F17: =B17&" - Opcion "&C17 -> Estimulo El Suelo es Lava - Nivel 1 - 6 - Opcion 1
A18: 17 | B18: =Estimulo!G7 -> Estimulo El Suelo es Lava - Nivel 1 - 6 | C18: 2 | D18: "6 Cuadernos" | E18: SI | F18: =B18&" - Opcion "&C18 -> Estimulo El Suelo es Lava - Nivel 1 - 6 - Opcion 2
A19: 18 | B19: =Estimulo!G7 -> Estimulo El Suelo es Lava - Nivel 1 - 6 | C19: 3 | D19: "6 Lapices" | E19: NO | F19: =B19&" - Opcion "&C19 -> Estimulo El Suelo es Lava - Nivel 1 - 6 - Opcion 3
A20: 19 | B20: =Estimulo!G8 -> Estimulo El Suelo es Lava - Nivel 1 - 7 | C20: 1 | D20: "5 Cuadernos" | E20: NO | F20: =B20&" - Opcion "&C20 -> Estimulo El Suelo es Lava - Nivel 1 - 7 - Opcion 1
A21: 20 | B21: =Estimulo!G8 -> Estimulo El Suelo es Lava - Nivel 1 - 7 | C21: 2 | D21: "6 Cuadernos" | E21: NO | F21: =B21&" - Opcion "&C21 -> Estimulo El Suelo es Lava - Nivel 1 - 7 - Opcion 2
A22: 21 | B22: =Estimulo!G8 -> Estimulo El Suelo es Lava - Nivel 1 - 7 | C22: 3 | D22: "4 Lapices" | E22: SI | F22: =B22&" - Opcion "&C22 -> Estimulo El Suelo es Lava - Nivel 1 - 7 - Opcion 3
A23: 22 | B23: =Estimulo!G9 -> Estimulo El Suelo es Lava - Nivel 2 - 1 | C23: 1 | D23: "3 Cuadernos Negros" | E23: NO | F23: =B23&" - Opcion "&C23 -> Estimulo El Suelo es Lava - Nivel 2 - 1 - Opcion 1
A24: 23 | B24: =Estimulo!G9 -> Estimulo El Suelo es Lava - Nivel 2 - 1 | C24: 2 | D24: "3 Cuadernos Negros" | E24: NO | F24: =B24&" - Opcion "&C24 -> Estimulo El Suelo es Lava - Nivel 2 - 1 - Opcion 2
A25: 24 | B25: =Estimulo!G9 -> Estimulo El Suelo es Lava - Nivel 2 - 1 | C25: 3 | D25: "3 Cuadernos Blancos" | E25: SI | F25: =B25&" - Opcion "&C25 -> Estimulo El Suelo es Lava - Nivel 2 - 1 - Opcion 3
A26: 25 | B26: =Estimulo!G10 -> Estimulo El Suelo es Lava - Nivel 2 - 2 | C26: 1 | D26: "6 Cuadernos Negros" | E26: NO | F26: =B26&" - Opcion "&C26 -> Estimulo El Suelo es Lava - Nivel 2 - 2 - Opcion 1
A27: 26 | B27: =Estimulo!G10 -> Estimulo El Suelo es Lava - Nivel 2 - 2 | C27: 2 | D27: "7 Lapices Negros" | E27: SI | F27: =B27&" - Opcion "&C27 -> Estimulo El Suelo es Lava - Nivel 2 - 2 - Opcion 2
A28: 27 | B28: =Estimulo!G10 -> Estimulo El Suelo es Lava - Nivel 2 - 2 | C28: 3 | D28: "6 Borradores Negros" | E28: NO | F28: =B28&" - Opcion "&C28 -> Estimulo El Suelo es Lava - Nivel 2 - 2 - Opcion 3
A29: 28 | B29: =Estimulo!G11 -> Estimulo El Suelo es Lava - Nivel 2 - 3 | C29: 1 | D29: "6 Lapices Negros" | E29: NO | F29: =B29&" - Opcion "&C29 -> Estimulo El Suelo es Lava - Nivel 2 - 3 - Opcion 1
A30: 29 | B30: =Estimulo!G11 -> Estimulo El Suelo es Lava - Nivel 2 - 3 | C30: 2 | D30: "6 Lapices Negros" | E30: NO | F30: =B30&" - Opcion "&C30 -> Estimulo El Suelo es Lava - Nivel 2 - 3 - Opcion 2
A31: 30 | B31: =Estimulo!G11 -> Estimulo El Suelo es Lava - Nivel 2 - 3 | C31: 3 | D31: "6 Borradores Negros" | E31: SI | F31: =B31&" - Opcion "&C31 -> Estimulo El Suelo es Lava - Nivel 2 - 3 - Opcion 3
A32: 31 | B32: =Estimulo!G12 -> Estimulo El Suelo es Lava - Nivel 3 - 1 | C32: 1 | D32: "8 Cuadernos Verdes" | E32: NO | F32: =B32&" - Opcion "&C32 -> Estimulo El Suelo es Lava - Nivel 3 - 1 - Opcion 1
A33: 32 | B33: =Estimulo!G12 -> Estimulo El Suelo es Lava - Nivel 3 - 1 | C33: 2 | D33: "8 Lapices Verdes" | E33: NO | F33: =B33&" - Opcion "&C33 -> Estimulo El Suelo es Lava - Nivel 3 - 1 - Opcion 2
A34: 33 | B34: =Estimulo!G12 -> Estimulo El Suelo es Lava - Nivel 3 - 1 | C34: 3 | D34: "8 Calculadoras Blancas" | E34: NO | F34: =B34&" - Opcion "&C34 -> Estimulo El Suelo es Lava - Nivel 3 - 1 - Opcion 3
A35: 34 | B35: =Estimulo!G12 -> Estimulo El Suelo es Lava - Nivel 3 - 1 | C35: 4 | D35: "9 Borradores Negros" | E35: SI | F35: =B35&" - Opcion "&C35 -> Estimulo El Suelo es Lava - Nivel 3 - 1 - Opcion 4
A36: 35 | B36: =Estimulo!G13 -> Estimulo El Suelo es Lava - Nivel 3 - 2 | C36: 1 | D36: "6 Calculadoras Negros" | E36: NO | F36: =B36&" - Opcion "&C36 -> Estimulo El Suelo es Lava - Nivel 3 - 2 - Opcion 1
A37: 36 | B37: =Estimulo!G13 -> Estimulo El Suelo es Lava - Nivel 3 - 2 | C37: 2 | D37: "8 Calculadoras Verdes" | E37: NO | F37: =B37&" - Opcion "&C37 -> Estimulo El Suelo es Lava - Nivel 3 - 2 - Opcion 2
A38: 37 | B38: =Estimulo!G13 -> Estimulo El Suelo es Lava - Nivel 3 - 2 | C38: 3 | D38: "7 Cuadernos Blancas" | E38: SI | F38: =B38&" - Opcion "&C38 -> Estimulo El Suelo es Lava - Nivel 3 - 2 - Opcion 3
A39: 38 | B39: =Estimulo!G13 -> Estimulo El Suelo es Lava - Nivel 3 - 2 | C39: 4 | D39: "9 Calculadoras Azules" | E39: NO | F39: =B39&" - Opcion "&C39 -> Estimulo El Suelo es Lava - Nivel 3 - 2 - Opcion 4
A40: 39 | B40: =Estimulo!G14 -> Estimulo Los Secretos del Chef - Nivel 1 - 1 | C40: 1 | D40: "Azul - Amarillo - Rojo, Azul - Amarillo - Rojo, Azul - Amarillo - Amarillo" | E40: SI | F40: =B40&" - Opcion "&C40 -> Estimulo Los Secretos del Chef - Nivel 1 - 1 - Opcion 1
...

Sheet Respuesta Estimulo
A1: Identificador | B1: Sesion | C1: Estimulo | D1: Cantidad Intentos | E1: Tiempo Restante | F1: Puntos | G1: CU
A2: 1 | B2: Estudiante: juan.ernesto6245@uco.edu.co - Inicio: 08/13/2025 1:10 PM - Fin: 08/13/2025 3:59 PM | C2: =Estimulo!G2 -> Estimulo El Suelo es Lava - Nivel 1 - 1 | D2: 1 | E2: 15s | F2: 0 | G2: =B2&" - "&C2 -> Estudiante: juan.ernesto6245@uco.edu.co - Inicio: 08/13/2025 1:10 PM - Fin: 08/13/2025 3:59 PM - Estimulo El Suelo es Lava - Nivel 1 - 1
A3: 2 | B3: Estudiante: juan.ernesto6245@uco.edu.co - Inicio: 08/13/2025 1:10 PM - Fin: 08/13/2025 3:59 PM | C3: =Estimulo!G3 -> Estimulo El Suelo es Lava - Nivel 1 - 2 | D3: 2 | E3: 30s | F3: 0 | G3: =B3&" - "&C3 -> Estudiante: juan.ernesto6245@uco.edu.co - Inicio: 08/13/2025 1:10 PM - Fin: 08/13/2025 3:59 PM - Estimulo El Suelo es Lava - Nivel 1 - 2
